2024-08-04 21:55:45,284 - instabot version: 0.117.0 (bot) - INFO - Instabot version: 0.117.0 Started
2024-08-04 21:55:45,284 - instabot version: 0.117.0 (bot) - DEBUG - Bot imported from C:\Users\Asus\Documents\Vishva_Projects\AI\Web_Scraper_bot\.venv\Lib\site-packages\instabot\bot\bot.py
2024-08-04 21:55:45,284 - instabot version: 0.117.0 (api_login) - INFO - Not yet logged in starting: PRE-LOGIN FLOW!
2024-08-04 21:55:57,356 - instabot version: 0.117.0 (api) - WARNING - HTTPSConnectionPool(host='i.instagram.com', port=443): Max retries exceeded with url: /api/v1/accounts/get_prefill_candidates/ (Caused by NameResolutionError("<urllib3.connection.HTTPSConnection object at 0x000001C222C84810>: Failed to resolve 'i.instagram.com' ([Errno 11001] getaddrinfo failed)"))
2024-08-04 21:55:57,364 - instabot version: 0.117.0 (api) - WARNING - HTTPSConnectionPool(host='i.instagram.com', port=443): Max retries exceeded with url: /api/v1/qe/sync/ (Caused by NameResolutionError("<urllib3.connection.HTTPSConnection object at 0x000001C222C86D10>: Failed to resolve 'i.instagram.com' ([Errno 11001] getaddrinfo failed)"))
2024-08-04 21:55:57,376 - instabot version: 0.117.0 (api) - WARNING - HTTPSConnectionPool(host='i.instagram.com', port=443): Max retries exceeded with url: /api/v1/launcher/sync/ (Caused by NameResolutionError("<urllib3.connection.HTTPSConnection object at 0x000001C222C8D190>: Failed to resolve 'i.instagram.com' ([Errno 11001] getaddrinfo failed)"))
2024-08-04 21:55:57,384 - instabot version: 0.117.0 (api) - WARNING - HTTPSConnectionPool(host='i.instagram.com', port=443): Max retries exceeded with url: /api/v1/accounts/contact_point_prefill/ (Caused by NameResolutionError("<urllib3.connection.HTTPSConnection object at 0x000001C222C8F5D0>: Failed to resolve 'i.instagram.com' ([Errno 11001] getaddrinfo failed)"))
